2020-04-16 13:55:59,471 INFO: Microblog startup [in D:\Programowanie\Flask_microblog\app\__init__.py:46]
2020-04-16 13:56:13,348 ERROR: Exception on /edit_profile [POST] [in d:\programowanie\flask_microblog\venv\lib\site-packages\flask\app.py:1891]
Traceback (most recent call last):
  File "d:\programowanie\flask_microblog\venv\lib\site-packages\sqlalchemy\engine\base.py", line 1248, in _execute_context
    cursor, statement, parameters, context
  File "d:\programowanie\flask_microblog\venv\lib\site-packages\sqlalchemy\engine\default.py", line 588, in do_execute
    cursor.execute(statement, parameters)
sqlite3.IntegrityError: UNIQUE constraint failed: user.username

The above exception was the direct cause of the following exception:

Traceback (most recent call last):
  File "d:\programowanie\flask_microblog\venv\lib\site-packages\flask\app.py", line 2446, in wsgi_app
    response = self.full_dispatch_request()
  File "d:\programowanie\flask_microblog\venv\lib\site-packages\flask\app.py", line 1951, in full_dispatch_request
    rv = self.handle_user_exception(e)
  File "d:\programowanie\flask_microblog\venv\lib\site-packages\flask\app.py", line 1820, in handle_user_exception
    reraise(exc_type, exc_value, tb)
  File "d:\programowanie\flask_microblog\venv\lib\site-packages\flask\_compat.py", line 39, in reraise
    raise value
  File "d:\programowanie\flask_microblog\venv\lib\site-packages\flask\app.py", line 1949, in full_dispatch_request
    rv = self.dispatch_request()
  File "d:\programowanie\flask_microblog\venv\lib\site-packages\flask\app.py", line 1935, in dispatch_request
    return self.view_functions[rule.endpoint](**req.view_args)
  File "d:\programowanie\flask_microblog\venv\lib\site-packages\flask_login\utils.py", line 272, in decorated_view
    return func(*args, **kwargs)
  File "D:\Programowanie\Flask_microblog\app\routes.py", line 125, in edit_profile
    db.session.commit()
  File "d:\programowanie\flask_microblog\venv\lib\site-packages\sqlalchemy\orm\scoping.py", line 162, in do
    return getattr(self.registry(), name)(*args, **kwargs)
  File "d:\programowanie\flask_microblog\venv\lib\site-packages\sqlalchemy\orm\session.py", line 1036, in commit
    self.transaction.commit()
  File "d:\programowanie\flask_microblog\venv\lib\site-packages\sqlalchemy\orm\session.py", line 503, in commit
    self._prepare_impl()
  File "d:\programowanie\flask_microblog\venv\lib\site-packages\sqlalchemy\orm\session.py", line 482, in _prepare_impl
    self.session.flush()
  File "d:\programowanie\flask_microblog\venv\lib\site-packages\sqlalchemy\orm\session.py", line 2496, in flush
    self._flush(objects)
  File "d:\programowanie\flask_microblog\venv\lib\site-packages\sqlalchemy\orm\session.py", line 2637, in _flush
    transaction.rollback(_capture_exception=True)
  File "d:\programowanie\flask_microblog\venv\lib\site-packages\sqlalchemy\util\langhelpers.py", line 69, in __exit__
    exc_value, with_traceback=exc_tb,
  File "d:\programowanie\flask_microblog\venv\lib\site-packages\sqlalchemy\util\compat.py", line 178, in raise_
    raise exception
  File "d:\programowanie\flask_microblog\venv\lib\site-packages\sqlalchemy\orm\session.py", line 2597, in _flush
    flush_context.execute()
  File "d:\programowanie\flask_microblog\venv\lib\site-packages\sqlalchemy\orm\unitofwork.py", line 422, in execute
    rec.execute(self)
  File "d:\programowanie\flask_microblog\venv\lib\site-packages\sqlalchemy\orm\unitofwork.py", line 589, in execute
    uow,
  File "d:\programowanie\flask_microblog\venv\lib\site-packages\sqlalchemy\orm\persistence.py", line 236, in save_obj
    update,
  File "d:\programowanie\flask_microblog\venv\lib\site-packages\sqlalchemy\orm\persistence.py", line 995, in _emit_update_statements
    statement, multiparams
  File "d:\programowanie\flask_microblog\venv\lib\site-packages\sqlalchemy\engine\base.py", line 984, in execute
    return meth(self, multiparams, params)
  File "d:\programowanie\flask_microblog\venv\lib\site-packages\sqlalchemy\sql\elements.py", line 293, in _execute_on_connection
    return connection._execute_clauseelement(self, multiparams, params)
  File "d:\programowanie\flask_microblog\venv\lib\site-packages\sqlalchemy\engine\base.py", line 1103, in _execute_clauseelement
    distilled_params,
  File "d:\programowanie\flask_microblog\venv\lib\site-packages\sqlalchemy\engine\base.py", line 1288, in _execute_context
    e, statement, parameters, cursor, context
  File "d:\programowanie\flask_microblog\venv\lib\site-packages\sqlalchemy\engine\base.py", line 1482, in _handle_dbapi_exception
    sqlalchemy_exception, with_traceback=exc_info[2], from_=e
  File "d:\programowanie\flask_microblog\venv\lib\site-packages\sqlalchemy\util\compat.py", line 178, in raise_
    raise exception
  File "d:\programowanie\flask_microblog\venv\lib\site-packages\sqlalchemy\engine\base.py", line 1248, in _execute_context
    cursor, statement, parameters, context
  File "d:\programowanie\flask_microblog\venv\lib\site-packages\sqlalchemy\engine\default.py", line 588, in do_execute
    cursor.execute(statement, parameters)
sqlalchemy.exc.IntegrityError: (sqlite3.IntegrityError) UNIQUE constraint failed: user.username
[SQL: UPDATE user SET username=?, about_me=? WHERE user.id = ?]
[parameters: ('Pawel', 'Jestem Susan i jestem testowym obiektem', 3)]
(Background on this error at: http://sqlalche.me/e/gkpj)
2020-04-22 14:25:14,367 INFO: Microblog startup [in D:\Programowanie\Flask_microblog\app\__init__.py:46]
2020-04-22 14:25:24,696 INFO: Microblog startup [in D:\Programowanie\Flask_microblog\app\__init__.py:46]
2020-04-22 15:02:31,200 INFO: Microblog startup [in D:\Programowanie\Flask_microblog\app\__init__.py:46]
2020-04-22 15:03:03,359 INFO: Microblog startup [in D:\Programowanie\Flask_microblog\app\__init__.py:46]
2020-04-22 15:03:35,768 INFO: Microblog startup [in D:\Programowanie\Flask_microblog\app\__init__.py:46]
2020-04-22 15:16:25,833 INFO: Microblog startup [in D:\Programowanie\Flask_microblog\app\__init__.py:46]
2020-04-23 10:10:01,292 INFO: Microblog startup [in D:\Programowanie\Flask_microblog\app\__init__.py:46]
2020-04-23 10:13:32,883 INFO: Microblog startup [in D:\Programowanie\Flask_microblog\app\__init__.py:46]
2020-04-23 10:15:03,952 ERROR: Exception on /login [POST] [in d:\programowanie\flask_microblog\venv\lib\site-packages\flask\app.py:1891]
Traceback (most recent call last):
  File "d:\programowanie\flask_microblog\venv\lib\site-packages\flask\app.py", line 2446, in wsgi_app
    response = self.full_dispatch_request()
  File "d:\programowanie\flask_microblog\venv\lib\site-packages\flask\app.py", line 1951, in full_dispatch_request
    rv = self.handle_user_exception(e)
  File "d:\programowanie\flask_microblog\venv\lib\site-packages\flask\app.py", line 1820, in handle_user_exception
    reraise(exc_type, exc_value, tb)
  File "d:\programowanie\flask_microblog\venv\lib\site-packages\flask\_compat.py", line 39, in reraise
    raise value
  File "d:\programowanie\flask_microblog\venv\lib\site-packages\flask\app.py", line 1949, in full_dispatch_request
    rv = self.dispatch_request()
  File "d:\programowanie\flask_microblog\venv\lib\site-packages\flask\app.py", line 1935, in dispatch_request
    return self.view_functions[rule.endpoint](**req.view_args)
  File "D:\Programowanie\Flask_microblog\app\routes.py", line 45, in login
    if user is None or not user.check_password(form.password.data):
  File "D:\Programowanie\Flask_microblog\app\models.py", line 60, in check_password
    return check_password_hash(self.password_hash, password)
  File "d:\programowanie\flask_microblog\venv\lib\site-packages\werkzeug\security.py", line 218, in check_password_hash
    if pwhash.count("$") < 2:
AttributeError: 'NoneType' object has no attribute 'count'
2020-04-23 10:15:12,446 ERROR: Exception on /login [POST] [in d:\programowanie\flask_microblog\venv\lib\site-packages\flask\app.py:1891]
Traceback (most recent call last):
  File "d:\programowanie\flask_microblog\venv\lib\site-packages\flask\app.py", line 2446, in wsgi_app
    response = self.full_dispatch_request()
  File "d:\programowanie\flask_microblog\venv\lib\site-packages\flask\app.py", line 1951, in full_dispatch_request
    rv = self.handle_user_exception(e)
  File "d:\programowanie\flask_microblog\venv\lib\site-packages\flask\app.py", line 1820, in handle_user_exception
    reraise(exc_type, exc_value, tb)
  File "d:\programowanie\flask_microblog\venv\lib\site-packages\flask\_compat.py", line 39, in reraise
    raise value
  File "d:\programowanie\flask_microblog\venv\lib\site-packages\flask\app.py", line 1949, in full_dispatch_request
    rv = self.dispatch_request()
  File "d:\programowanie\flask_microblog\venv\lib\site-packages\flask\app.py", line 1935, in dispatch_request
    return self.view_functions[rule.endpoint](**req.view_args)
  File "D:\Programowanie\Flask_microblog\app\routes.py", line 45, in login
    if user is None or not user.check_password(form.password.data):
  File "D:\Programowanie\Flask_microblog\app\models.py", line 60, in check_password
    return check_password_hash(self.password_hash, password)
  File "d:\programowanie\flask_microblog\venv\lib\site-packages\werkzeug\security.py", line 218, in check_password_hash
    if pwhash.count("$") < 2:
AttributeError: 'NoneType' object has no attribute 'count'
2020-04-23 10:25:37,203 INFO: Microblog startup [in D:\Programowanie\Flask_microblog\app\__init__.py:46]
2020-04-23 10:34:06,650 INFO: Microblog startup [in D:\Programowanie\Flask_microblog\app\__init__.py:46]
2020-04-23 10:43:14,822 INFO: Microblog startup [in D:\Programowanie\Flask_microblog\app\__init__.py:46]
